//try catch verifica error
// y ve desde donde se encuentra el error
const numero = 1;
const numero2 = 2;

//es para prueba de errores
try {
console.log(numero3);
} catch (error) {
    console.log(error);
}
